Workbook
Name _1: #N/A
Name _1000A01: #N/A
Name _2: #N/A
Name _CON1: #REF!
Name _CON1: #REF!
Name _CON2: #REF!
Name _CON2: #REF!
Name _NET2: #REF!
Name _NET2: #REF!
Name A01_: #N/A
Name A01AC: #N/A
Name A01CAT: #N/A
Name A01CODE: #N/A
Name A01DATA: #N/A
Name A01MI: #N/A
Name A01TO: #N/A
Name AA: #REF!
Name AA: #REF!
Name All_Item: #REF!
Name All_Item: #REF!
Name ALPIN: #N/A
Name ALPJYOU: #N/A
Name ALPTOI: #N/A
Name BB: #REF!
Name BB: #REF!
Name bieu2: #REF!
Name bieu2: #REF!
Name BL: "$A$1:$f$11"
Name BOQ: #REF!
Name BOQ: #REF!
Name BVCISUMMARY: #REF!
Name BVCISUMMARY: #REF!
Name Category_All: #REF!
Name Category_All: #REF!
Name CATIN: #N/A
Name CATJYOU: #N/A
Name CATREC: #N/A
Name CATSYU: #N/A
Name CLVC3: 0.1
Name COMMON: #REF!
Name COMMON: #REF!
Name CON_EQP_COS: #REF!
Name CON_EQP_COS: #REF!
Name CON_EQP_COST: #REF!
Name CON_EQP_COST: #REF!
Name CONST_EQ: #REF!
Name CONST_EQ: #REF!
Name COVER: #REF!
Name COVER: #REF!
Name CRITINST: #REF!
Name CRITINST: #REF!
Name CRITPURC: #REF!
Name CRITPURC: #REF!
Name CS_10: #REF!
Name CS_10: #REF!
Name CS_100: #REF!
Name CS_100: #REF!
Name CS_10S: #REF!
Name CS_10S: #REF!
Name CS_120: #REF!

Sheet PL5 DƠN GIÁ CHI TIẾT
A1: Phụ lục: KẾ HOẠCH CHI TIÊU NGÂN SÁCH NGÀNH QUÂN KHÍ NĂM 2026 | Z1: =G5-AA1 -> 34.1107 | AA1: 939.784 | AH1: 0.69517
A2: TT | B2: Nội dung công việc | C2: Kế hoạch SL | F2: Kinh phí (tr.đồng) | J2: Đơn giá (Nghìn đồng) | N2: Tiến độ thực hiện | V2: CQ, đơn vị thực hiện | Y2: Ghi chú | AA2: =32-Z1 -> -2.1107 | AH2: 939.09083
C3: ĐVT | D3: Chỉ tiêu | E3: KH | N3: Quí I | P3: Quí II | R3: Quí III | T3: Quí IV | V3: PX | W3: Ban | X3: chỉ đạo | AH3: 939.786
F4: Tổng | G4: Tự chi | H4: Hiện vật | I4: Dầu mỡ KT | J4: + | K4: Tự chi | L4: Hiện vật | M4: Dầu mỡ KT | N4: SL | O4: NS (TC) | P4: SL | Q4: NS (TC) | R4: SL | S4: NS (TC) | T4: SL | U4: NS (TC) | AH4: =AH3-AH2 -> 0.69517
A5: I | B5: Ngành Quân khí | D5: =D6+D16+D18+D45 -> 4456 | E5: =E6+E16+E18+E45+E48+E50 -> 4456 | F5: =F6+F16+F18+F45+F48+F50 -> 1533.9207 | G5: =G6+G16+G18+G45+G48+G50 -> 973.8947 | H5: =H6+H16+H18+H45+H48+H50 -> 56.5196 | I5: =I6+I16+I18+I45+I48+I50 -> 503.50637 | N5: =N6+N16+N18+N45+N48+N50 -> 1589 | O5: =O6+O16+O18+O45+O48+O50 -> 178.53209 | P5: =P6+P16+P18+P45+P48+P50 -> 1985 | Q5: =Q6+Q16+Q18+Q45+Q48+Q50 -> 446.16163 | R5: =R6+R16+R18+R45+R48+R50 -> 723 | S5: =S6+S16+S18+S45+S48+S50 -> 292.20633 | T5: =T6+T16+T18+T45+T48+T50 -> 858 | U5: =U6+U16+U18+U45+U48+U50 -> 55.49465
A6: 1 | B6: SCV Vũ khí, khí tài | D6: =D7+D8+D9+D10+D11+D12+D13+D14 -> 2890 | E6: =E7+E8+E9+E10+E11+E12+E13+E14 -> 2890 | F6: =SUM(F7:F15) -> 892.25767 | G6: =SUM(G7:G15) -> 332.2317 | H6: =SUM(H7:H15) -> 56.5196 | I6: =SUM(I7:I15) -> 503.50637 | N6: =SUM(N7:N15) -> 1586 | O6: =SUM(O7:O15) -> 92.19359 | P6: =SUM(P7:P15) -> 1978 | Q6: =SUM(Q7:Q15) -> 133.70313 | R6: =SUM(R7:R15) -> 722 | S6: =SUM(S7:S15) -> 51.04483 | T6: =SUM(T7:T15) -> 857 | U6: =SUM(U7:U15) -> 55.29015 | V6: VK | W6: KH, KT | X6: BGĐ | Z6: =SUM(D6:F6) -> 6672.2577 | AA6: =F6/E6 -> 0.30873968 | AB6: PMĐ, PCT | AD6: 1
A7: - | B7: Pháo mặt đất | C7: Khẩu | D7: 9 | E7: =D7 -> 9 | F7: =E7*SUM(K7:M7)/1000 -> 59.72319 | G7: =$E7*K7/1000 -> 13.4577 | H7: =$E7*L7/1000 -> 36.90351 | I7: =$E7*M7/1000 -> 9.36198 | J7: =SUM(K7:M7) -> 6635.91 | K7: 1495.3 | L7: 4100.39 | M7: 1040.22 | O7: =N7*$K7/1000 -> 0 | P7: 6 | Q7: =P7*$K7/1000 -> 8.9718 | R7: 1 | S7: =R7*$K7/1000 -> 1.4953 | T7: 2 | U7: =T7*$K7/1000 -> 2.9906 | V7: " | W7: " | X7: " | Z7: =SUM(D7:F7) -> 77.72319 | AA7: =F7/E7 -> 6.63591 | AB7: =Z7+Z8 -> 102.81219 | AC7: =F7/E7 -> 6.63591
A8: - | B8: Pháo chống tăng | C8: Khẩu | D8: 5 | E8: =D8 -> 5 | F8: =E8*SUM(K8:M8)/1000 -> 15.089 | G8: =$E8*K8/1000 -> 5.40835 | H8: =$E8*L8/1000 -> 5.95315 | I8: =$E8*M8/1000 -> 3.7275 | J8: =SUM(K8:M8) -> 3017.8 | K8: 1081.67 | L8: 1190.63 | M8: 745.5 | N8: 1 | O8: =N8*$K8/1000 -> 1.08167 | P8: 3 | Q8: =P8*$K8/1000 -> 3.24501 | R8: 1 | S8: =R8*$K8/1000 -> 1.08167 | U8: =T8*$K8/1000 -> 0 | V8: " | W8: " | X8: " | Z8: =SUM(D8:F8) -> 25.089 | AA8: =F8/E8 -> 3.0178 | AC8: =F8/E8 -> 3.0178
A9: - | B9: Pháo Cao xạ | C9: Khẩu | D9: 12 | E9: =D9 -> 12 | F9: =E9*SUM(K9:M9)/1000 -> 29.03532 | G9: =$E9*K9/1000 -> 9.11568 | H9: =$E9*L9/1000 -> 5.20152 | I9: =$E9*M9/1000 -> 14.71812 | J9: =SUM(K9:M9) -> 2419.61 | K9: 759.64 | L9: 433.46 | M9: 1226.51 | N9: 2 | O9: =N9*$K9/1000 -> 1.51928 | P9: 7 | Q9: =P9*$K9/1000 -> 5.31748 | R9: 2 | S9: =R9*$K9/1000 -> 1.51928 | T9: 1 | U9: =T9*$K9/1000 -> 0.75964 | V9: " | W9: " | X9: " | Z9: =SUM(D9:F9) -> 53.03532 | AA9: =F9/E9 -> 2.41961 | AB9: SBB | AC9: =F9/E9 -> 2.41961
A10: - | B10: Súng ĐKZ | C10: Khẩu | D10: 20 | E10: =D10 -> 20 | F10: =E10*SUM(K10:M10)/1000 -> 11.913 | G10: =$E10*K10/1000 -> 6.4294 | H10: =$E10*L10/1000 -> 0.1202 | I10: =$E10*M10/1000 -> 5.3634 | J10: =SUM(K10:M10) -> 595.65 | K10: 321.47 | L10: 6.01 | M10: 268.17 | N10: 6 | O10: =N10*$K10/1000 -> 1.92882 | P10: 5 | Q10: =P10*$K10/1000 -> 1.60735 | R10: 7 | S10: =R10*$K10/1000 -> 2.25029 | T10: 2 | U10: =T10*$K10/1000 -> 0.64294 | V10: " | W10: " | X10: " | AC10: =F10/E10 -> 0.59565
A11: - | B11: Súng cối | C11: Khẩu | D11: 58 | E11: =D11 -> 58 | F11: =E11*SUM(K11:M11)/1000 -> 33.42424 | G11: =$E11*K11/1000 -> 19.31168 | H11: =$E11*L11/1000 -> 0.22968 | I11: =$E11*M11/1000 -> 13.88288 | J11: =SUM(K11:M11) -> 576.28 | K11: 332.96 | L11: 3.96 | M11: 239.36 | N11: 4 | O11: =N11*$K11/1000 -> 1.33184 | P11: 19 | Q11: =P11*$K11/1000 -> 6.32624 | R11: 14 | S11: =R11*$K11/1000 -> 4.66144 | T11: 21 | U11: =T11*$K11/1000 -> 6.99216 | V11: " | W11: " | X11: " | AC11: =F11/E11 -> 0.57628
A12: - | B12: Súng Cao xạ | C12: Khẩu | D12: 33 | E12: =D12 -> 33 | F12: =E12*SUM(K12:M12)/1000 -> 26.53893 | G12: =$E12*K12/1000 -> 11.5269 | H12: =$E12*L12/1000 -> 0.48345 | I12: =$E12*M12/1000 -> 14.52858 | J12: =SUM(K12:M12) -> 804.21 | K12: 349.3 | L12: 14.65 | M12: 440.26 | N12: 6 | O12: =N12*$K12/1000 -> 2.0958 | P12: 13 | Q12: =P12*$K12/1000 -> 4.5409 | R12: 12 | S12: =R12*$K12/1000 -> 4.1916 | T12: 2 | U12: =T12*$K12/1000 -> 0.6986 | V12: " | W12: " | X12: " | AC12: =F12/E12 -> 0.80421
A13: - | B13: Súng bộ binh | C13: Khẩu | D13: 2470 | E13: =D13 -> 2470 | F13: =E13*SUM(K13:M13)/1000 -> 343.9969 | G13: =$E13*K13/1000 -> 112.8543 | H13: =$E13*L13/1000 -> 5.5328 | I13: =$E13*M13/1000 -> 225.6098 | J13: =SUM(K13:M13) -> 139.27 | K13: 45.69 | L13: 2.24 | M13: 91.34 | N13: =543+83+79+60 -> 765 | O13: =N13*$K13/1000 -> 34.95285 | P13: =25+5+293+367+2+30+232 -> 954 | Q13: =P13*$K13/1000 -> 43.58826 | R13: =5+54+11+104+150 -> 324 | S13: =R13*$K13/1000 -> 14.80356 | T13: =126+50+251 -> 427 | U13: =T13*$K13/1000 -> 19.50963 | V13: " | W13: " | X13: " | AC13: =F13/E13 -> 0.13927
A14: - | B14: Khí tài quang học | C14: Cái | D14: 283 | E14: =D14 -> 283 | F14: =E14*SUM(K14:M14)/1000 -> 11.74167 | G14: =$E14*K14/1000 -> 9.84557 | H14: =$E14*L14/1000 -> 0 | I14: =$E14*M14/1000 -> 1.8961 | J14: =SUM(K14:M14) -> 41.49 | K14: 34.79 | L14: 0 | M14: 6.7 | N14: 71 | O14: =N14*$K14/1000 -> 2.47009 | P14: 71 | Q14: =P14*$K14/1000 -> 2.47009 | R14: 71 | S14: =R14*$K14/1000 -> 2.47009 | T14: 70 | U14: =T14*$K14/1000 -> 2.4353 | V14: " | W14: " | X14: " | AC14: =F14/E14 -> 0.04149
A15: - | B15: Nhuộm đen | C15: Khẩu | D15: 2253 | E15: =D15 -> 2253 | F15: =E15*SUM(K15:M15)/1000 -> 360.79542 | G15: =$E15*K15/1000 -> 144.28212 | H15: =$E15*L15/1000 -> 2.09529 | I15: =$E15*M15/1000 -> 214.41801 | J15: =SUM(K15:M15) -> 160.14 | K15: 64.04 | L15: 0.93 | M15: 95.17 | N15: 731 | O15: =N15*$K15/1000 -> 46.81324 | P15: 900 | Q15: =P15*$K15/1000 -> 57.636 | R15: 290 | S15: =R15*$K15/1000 -> 18.5716 | T15: =D15-N15-P15-R15 -> 332 | U15: =T15*$K15/1000 -> 21.26128 | V15: " | W15: " | X15: " | AC15: =F15/E15 -> 0.16014
A16: 2 | B16: Sửa chữa TTB CN | D16: 5 | E16: 5 | F16: =F17 -> 16 | G16: =F16 -> 16 | P16: =P17 -> 5 | Q16: =Q17 -> 16 | S16: =R16*AC16 -> 0 | U16: =U17 -> 0 | V16: CK | W16: KH, KT | X16: BGĐ | AC16: =F16/E16 -> 3.2
A17: - | B17: Sửa chữa giá súng | C17: Cái | D17: 5 | E17: 5 | F17: =SUM(G17:I17) -> 16 | G17: =E17*K17/1000 -> 16 | K17: 3200 | P17: 5 | Q17: =P17*AC17 -> 16 | S17: =R17*AC17 -> 0 | U17: =T17*AC17 -> 0 | V17: " | W17: " | X17: " | Z17: =SUM(D17:F17) -> 26 | AA17: =F17/E17 -> 3.2 | AB17: KTQH | AC17: =F17/E17 -> 3.2
A18: 3 | B18: Đồng bộ VKTBKT (nhiệm vụ TX) | D18: =SUM(D19,D33,D42) -> 1560 | E18: =D18 -> 1560 | F18: =SUM(F19,F33,F42) -> 534.601 | G18: =SUM(G19,G33,G42) -> 534.601 | O18: =SUM(O19,O33,O42) -> 35.89 | Q18: =SUM(Q19,Q33,Q42) -> 256.254 | S18: =SUM(S19,S33,S42) -> 240.957 | U18: =SUM(U19,U33,U42) -> 0 | V18: CK | W18: KH, KT | X18: BGĐ | Z18: =SUM(D18:F18) -> 3654.601 | AA18: =F18/E18 -> 0.34269295 | AB18: 541 | AC18: =F18/E18 -> 0.34269295 | AD18: 1
A19: - | B19: SX chi tiết cơ khí | C19: Bộ, Cái | D19: =E19 -> 1030 | E19: =SUM(E20:E32) -> 1030 | F19: =SUM(F20:F32) -> 182.374 | G19: =SUM(G20:G32) -> 182.374 | N19: =SUM(N20:N32) -> 570 | O19: =SUM(O20:O32) -> 35.89 | P19: =SUM(P20:P32) -> 90 | Q19: =SUM(Q20:Q32) -> 23.064 | R19: =SUM(R20:R32) -> 330 | S19: =SUM(S20:S32) -> 121.92 | T19: =SUM(T20:T32) -> 0 | U19: =SUM(U20:U32) -> 0 | V19: " | W19: " | X19: " | Z19: =SUM(D19:F19) -> 2242.374 | AA19: =F19/E19 -> 0.17706214 | AC19: =F19/E19 -> 0.17706214
B20: Khuy dây đeo AK | C20: Cái | D20: =E20 -> 500 | E20: 500 | F20: =SUM(G20:I20) -> 7.5 | G20: =K20*E20 -> 7.5 | K20: 0.015 | N20: =E20 -> 500 | O20: =K20*N20 -> 7.5 | Q20: =K20*P20 -> 0 | S20: =R20*$K20 -> 0 | U20: =T20*$K20 -> 0
B21: Đế báng AK + vít | C21: Bộ | D21: =E21 -> 300 | E21: 300 | F21: =SUM(G21:I21) -> 110.4 | G21: =K21*E21 -> 110.4 | K21: 0.368 | O21: =K21*N21 -> 0 | Q21: =K21*P21 -> 0 | R21: =E21 -> 300 | S21: =R21*$K21 -> 110.4 | U21: =T21*$K21 -> 0
B22: Bộ phát hoả K54 | C22: Bộ | D22: =E22 -> 30 | E22: 30 | F22: =SUM(G22:I22) -> 11.52 | G22: =K22*E22 -> 11.52 | K22: 0.384 | O22: =K22*N22 -> 0 | Q22: =K22*P22 -> 0 | R22: =E22 -> 30 | S22: =R22*$K22 -> 11.52 | U22: =T22*$K22 -> 0
B23: Nhíp cò RPĐ | C23: Cái | D23: =E23 -> 40 | E23: 40 | F23: =SUM(G23:I23) -> 1.2 | G23: =K23*E23 -> 1.2 | K23: 0.03 | N23: 20 | O23: =K23*N23 -> 0.6 | Q23: =K23*P23 -> 0 | S23: =R23*$K23 -> 0 | U23: =T23*$K23 -> 0
B24: Nắp che bụi RPĐ | C24: Bộ | D24: =E24 -> 40 | E24: 40 | F24: =SUM(G24:I24) -> 1.8 | G24: =K24*E24 -> 1.8 | K24: 0.045 | N24: 20 | O24: =K24*N24 -> 0.9 | Q24: =K24*P24 -> 0 | S24: =R24*$K24 -> 0 | U24: =T24*$K24 -> 0
B25: Khoá an toàn + nhíp RPĐ | C25: Bộ | D25: =E25 -> 20 | E25: 20 | F25: =SUM(G25:I25) -> 18.48 | G25: =K25*E25 -> 18.48 | K25: 0.924 | N25: 20 | O25: =K25*N25 -> 18.48 | Q25: =K25*P25 -> 0 | S25: =R25*$K25 -> 0 | U25: =T25*$K25 -> 0
B26: Vòng bịt kín khi thuốc Cối 100 | C26: Bộ | D26: =E26 -> 20 | E26: 20 | F26: =SUM(G26:I26) -> 3.222 | G26: =K26*E26 -> 3.222 | K26: =0.3222/2 -> 0.1611 | O26: =K26*N26 -> 0 | P26: =E26 -> 20 | Q26: =K26*P26 -> 3.222 | S26: =R26*$K26 -> 0 | U26: =T26*$K26 -> 0
B27: Vòng bịt kín khi thuốc Cối 82 | C27: Bộ | D27: =E27 -> 20 | E27: 20 | F27: =SUM(G27:I27) -> 3.222 | G27: =K27*E27 -> 3.222 | K27: 0.1611 | O27: =K27*N27 -> 0 | P27: =E27 -> 20 | Q27: =K27*P27 -> 3.222 | S27: =R27*$K27 -> 0 | U27: =T27*$K27 -> 0
B28: Khoá đế cối 60mm | C28: Bộ | D28: =E28 -> 10 | E28: 10 | F28: =SUM(G28:I28) -> 8.41 | G28: =K28*E28 -> 8.41 | K28: 0.841 | N28: 10 | O28: =K28*N28 -> 8.41 | Q28: =K28*P28 -> 0 | S28: =R28*$K28 -> 0 | U28: =T28*$K28 -> 0
B29: Tay nắm nắp hậu 12,7mm | C29: Bộ | D29: =E29 -> 20 | E29: 20 | F29: =SUM(G29:I29) -> 2.1 | G29: =K29*E29 -> 2.1 | K29: 0.105 | O29: =K29*N29 -> 0 | P29: =E29 -> 20 | Q29: =K29*P29 -> 2.1 | S29: =R29*$K29 -> 0 | U29: =T29*$K29 -> 0
B30: Then hãm nòng + Đai ốc 12,7mm | C30: Bộ | D30: =E30 -> 10 | E30: 10 | F30: =SUM(G30:I30) -> 7.62 | G30: =K30*E30 -> 7.62 | K30: 0.762 | O30: =K30*N30 -> 0 | P30: =E30 -> 10 | Q30: =K30*P30 -> 7.62 | S30: =R30*$K30 -> 0 | U30: =T30*$K30 -> 0
B31: Bọt nước giường PCX 37 | C31: Bộ | D31: =E31 -> 10 | E31: 10 | F31: =SUM(G31:I31) -> 5.4 | G31: =K31*E31 -> 5.4 | K31: 0.54 | O31: =K31*N31 -> 0 | P31: =E31 -> 10 | Q31: =K31*P31 -> 5.4 | S31: =R31*$K31 -> 0 | U31: =T31*$K31 -> 0
B32: Bạc giảm xóc PCX 37 | C32: Cái | D32: =E32 -> 10 | E32: 10 | F32: =SUM(G32:I32) -> 1.5 | G32: =K32*E32 -> 1.5 | K32: 0.15 | O32: =K32*N32 -> 0 | P32: 10 | Q32: =K32*P32 -> 1.5 | S32: =R32*$K32 -> 0 | U32: =T32*$K32 -> 0
A33: - | B33: Chi tiết nhựa | C33: Bộ | D33: =E33 -> 360 | E33: =SUM(E34:E41) -> 360 | F33: =SUM(F34:F41) -> 186.957 | G33: =SUM(G34:G41) -> 186.957 | N33: =SUM(N34:N41) -> 0 | O33: =SUM(O34:O41) -> 0 | P33: =SUM(P34:P41) -> 240 | Q33: =SUM(Q34:Q41) -> 114.24 | R33: =SUM(R34:R41) -> 120 | S33: =SUM(S34:S41) -> 72.717 | T33: =SUM(T34:T41) -> 0 | U33: =SUM(U34:U41) -> 0 | V33: " | W33: " | X33: " | AC33: =F33/E33 -> 0.519325
B34: Ốp lót tay dưới AK | C34: Bộ | D34: =E34 -> 80 | E34: 80 | F34: =SUM(G34:I34) -> 35.52 | G34: =K34*E34 -> 35.52 | K34: 0.444 | O34: =K34*N34 -> 0 | P34: =E34 -> 80 | Q34: =K34*P34 -> 35.52 | S34: =R34*$K34 -> 0 | U34: =T34*$K34 -> 0
B35: Ốp lót tay trên AK | C35: Bộ | D35: =E35 -> 80 | E35: =E34 -> 80 | F35: =SUM(G35:I35) -> 64.08 | G35: =K35*E35 -> 64.08 | K35: 0.801 | O35: =K35*N35 -> 0 | P35: =E35 -> 80 | Q35: =K35*P35 -> 64.08 | S35: =R35*$K35 -> 0 | U35: =T35*$K35 -> 0
B36: Tay cầm AK | C36: Bộ | D36: =E36 -> 80 | E36: 80 | F36: =SUM(G36:I36) -> 14.64 | G36: =K36*E36 -> 14.64 | K36: 0.183 | O36: =K36*N36 -> 0 | P36: =E36 -> 80 | Q36: =K36*P36 -> 14.64 | S36: =R36*$K36 -> 0 | U36: =T36*$K36 -> 0
B37: Báng súng AKM | C37: Bộ | D37: =E37 -> 50 | E37: 50 | F37: =SUM(G37:I37) -> 50 | G37: =K37*E37 -> 50 | K37: 1 | O37: =K37*N37 -> 0 | Q37: =K37*P37 -> 0 | R37: =E37 -> 50 | S37: =R37*$K37 -> 50 | U37: =T37*$K37 -> 0
B38: Ốp tay cầm K54 | C38: Bộ | D38: =E38 -> 40 | E38: 40 | F38: =SUM(G38:I38) -> 4.124 | G38: =K38*E38 -> 4.124 | K38: 0.1031 | O38: =K38*N38 -> 0 | Q38: =K38*P38 -> 0 | R38: =E38 -> 40 | S38: =R38*$K38 -> 4.124 | U38: =T38*$K38 -> 0
B39: Ốp chống nóng + đai ốc B41 | C39: Bộ | D39: =E39 -> 10 | E39: 10 | F39: =SUM(G39:I39) -> 8.743 | G39: =K39*E39 -> 8.743 | K39: 0.8743 | O39: =K39*N39 -> 0 | Q39: =K39*P39 -> 0 | R39: =E39 -> 10 | S39: =R39*$K39 -> 8.743 | U39: =T39*$K39 -> 0
B40: Ốp tay cò B41 | C40: Bộ | D40: =E40 -> 10 | E40: 10 | F40: =SUM(G40:I40) -> 2.65 | G40: =K40*E40 -> 2.65 | K40: 0.265 | O40: =K40*N40 -> 0 | Q40: =K40*P40 -> 0 | R40: =E40 -> 10 | S40: =R40*$K40 -> 2.65 | U40: =T40*$K40 -> 0
...

Sheet Sheet3
A1: CHI TIẾT | B1: ĐƠN GIÁ | C1: Thép cuộn
A2: ='PL5 DƠN GIÁ CHI TIẾT'!B20 -> Khuy dây đeo AK | B2: ='PL5 DƠN GIÁ CHI TIẾT'!K20*1000 -> 15
A3: ='PL5 DƠN GIÁ CHI TIẾT'!B21 -> Đế báng AK + vít | B3: ='PL5 DƠN GIÁ CHI TIẾT'!K21*1000 -> 368
A4: ='PL5 DƠN GIÁ CHI TIẾT'!B22 -> Bộ phát hoả K54 | B4: ='PL5 DƠN GIÁ CHI TIẾT'!K22*1000 -> 384
A5: ='PL5 DƠN GIÁ CHI TIẾT'!B23 -> Nhíp cò RPĐ | B5: ='PL5 DƠN GIÁ CHI TIẾT'!K23*1000 -> 30
A6: ='PL5 DƠN GIÁ CHI TIẾT'!B24 -> Nắp che bụi RPĐ | B6: ='PL5 DƠN GIÁ CHI TIẾT'!K24*1000 -> 45
A7: ='PL5 DƠN GIÁ CHI TIẾT'!B25 -> Khoá an toàn + nhíp RPĐ | B7: ='PL5 DƠN GIÁ CHI TIẾT'!K25*1000 -> 924
A8: ='PL5 DƠN GIÁ CHI TIẾT'!B26 -> Vòng bịt kín khi thuốc Cối 100 | B8: ='PL5 DƠN GIÁ CHI TIẾT'!K26*1000 -> 161.1
A9: ='PL5 DƠN GIÁ CHI TIẾT'!B27 -> Vòng bịt kín khi thuốc Cối 82 | B9: ='PL5 DƠN GIÁ CHI TIẾT'!K27*1000 -> 161.1
A10: ='PL5 DƠN GIÁ CHI TIẾT'!B28 -> Khoá đế cối 60mm | B10: ='PL5 DƠN GIÁ CHI TIẾT'!K28*1000 -> 841
A11: ='PL5 DƠN GIÁ CHI TIẾT'!B29 -> Tay nắm nắp hậu 12,7mm | B11: ='PL5 DƠN GIÁ CHI TIẾT'!K29*1000 -> 105
A12: ='PL5 DƠN GIÁ CHI TIẾT'!B30 -> Then hãm nòng + Đai ốc 12,7mm | B12: ='PL5 DƠN GIÁ CHI TIẾT'!K30*1000 -> 762
A13: ='PL5 DƠN GIÁ CHI TIẾT'!B31 -> Bọt nước giường PCX 37 | B13: ='PL5 DƠN GIÁ CHI TIẾT'!K31*1000 -> 540
... A26: ='PL5 DƠN GIÁ CHI TIẾT'!B44 -> Báng súng CKC | B26: ='PL5 DƠN GIÁ CHI TIẾT'!K44*1000 -> 1158

Sheet Sheet1
